<mujoco model="h1">
    <compiler angle="radian" meshdir="assets" autolimits="true"/>

    <statistic meansize="0.05"/>

    <default>
    <default class="h1">
        <joint damping="1" armature="0.1"/>
        <default class="visual">
            <geom type="mesh" contype="0" conaffinity="0" group="2" material="black"/>
        </default>
        <default class="collision">
            <geom group="3" mass="0" density="0"/>
            <default class="foot">
                <geom type="capsule" size=".014"/>
                <default class="foot1">
                    <geom fromto="-.035 0 -0.056 .02 0 -0.045"/>
                </default>
                <default class="foot2">
                    <geom fromto=".02 0 -0.045 .115 0 -0.056"/>
                </default>
                <default class="foot3">
                    <geom fromto=".14 -.03 -0.056 .14 .03 -0.056"/>
                </default>
            </default>
        </default>
        <site size="0.01" rgba="1 0 0 1" group="4"/>
    </default>
    <default class="hand">
        <joint damping="0.5"/>
        <motor ctrllimited="true" ctrlrange="-3 3" gear="1"/>
        <position ctrllimited="true" kp="10"/>
    </default>
    </default>

    <asset>
        <material name="black" rgba="0.1 0.1 0.1 1"/>
        <material name="white" rgba="1 1 1 1"/>

        <mesh file="pelvis.stl"/>
        <mesh file="left_hip_yaw_link.stl"/>
        <mesh file="left_hip_roll_link.stl"/>
        <mesh file="left_hip_pitch_link.stl"/>
        <mesh file="left_knee_link.stl"/>
        <mesh file="left_ankle_link.stl"/>
        <mesh file="right_hip_yaw_link.stl"/>
        <mesh file="right_hip_roll_link.stl"/>
        <mesh file="right_hip_pitch_link.stl"/>
        <mesh file="right_knee_link.stl"/>
        <mesh file="right_ankle_link.stl"/>
        <mesh file="torso_link.stl"/>
        <mesh file="left_shoulder_pitch_link.stl"/>
        <mesh file="left_shoulder_roll_link.stl"/>
        <mesh file="left_shoulder_yaw_link.stl"/>
        <!--<mesh file="left_elbow_link.stl"/>-->
        <!--hands ready ver-->
        <mesh file="left_elbow_link.STL"/>
        <mesh file="right_shoulder_pitch_link.stl"/>
        <mesh file="right_shoulder_roll_link.stl"/>
        <mesh file="right_shoulder_yaw_link.stl"/>
        <!--<mesh file="right_elbow_link.stl"/>-->
        <!--hands ready ver-->
        <mesh file="right_elbow_link.STL"/>
        <mesh file="logo_link.stl"/>

        <mesh name="l_palm_vis" file="meshes/inspire_hands/lh_base_link.STL"/>
        <mesh name="l_palm_col" file="meshes/inspire_hands/lh_base_link.STL"/>
        <mesh name="l_thumb_proximal_1_vis" file="meshes/inspire_hands/lh_Link11.STL"/>
        <mesh name="l_thumb_proximal_1_col" file="meshes/inspire_hands/lh_Link11.STL"/>
        <mesh name="l_thumb_proximal_2_vis" file="meshes/inspire_hands/lh_Link12.STL"/>
        <mesh name="l_thumb_proximal_2_col" file="meshes/inspire_hands/lh_Link12.STL"/>
        <mesh name="l_thumb_middle_vis" file="meshes/inspire_hands/lh_Link13.STL"/>
        <mesh name="l_thumb_middle_col" file="meshes/inspire_hands/lh_Link13.STL"/>
        <mesh name="l_thumb_distal_vis" file="meshes/inspire_hands/lh_Link14.STL"/>
        <mesh name="l_thumb_distal_col" file="meshes/inspire_hands/lh_Link14.STL"/>
        <mesh name="l_index_proximal_vis" file="meshes/inspire_hands/lh_Link15.STL"/>
        <mesh name="l_index_proximal_col" file="meshes/inspire_hands/lh_Link15.STL"/>
        <mesh name="l_index_distal_vis" file="meshes/inspire_hands/lh_Link16.STL"/>
        <mesh name="l_index_distal_col" file="meshes/inspire_hands/lh_Link16.STL"/>
        <mesh name="l_middle_proximal_vis" file="meshes/inspire_hands/lh_Link17.STL"/>
        <mesh name="l_middle_proximal_col" file="meshes/inspire_hands/lh_Link17.STL"/>
        <mesh name="l_middle_distal_vis" file="meshes/inspire_hands/lh_Link18.STL"/>
        <mesh name="l_middle_distal_col" file="meshes/inspire_hands/lh_Link18.STL"/>
        <mesh name="l_ring_proximal_vis" file="meshes/inspire_hands/lh_Link19.STL"/>
        <mesh name="l_ring_proximal_col" file="meshes/inspire_hands/lh_Link19.STL"/>
        <mesh name="l_ring_distal_vis" file="meshes/inspire_hands/lh_Link20.STL"/>
        <mesh name="l_ring_distal_col" file="meshes/inspire_hands/lh_Link20.STL"/>
        <mesh name="l_pinky_proximal_vis" file="meshes/inspire_hands/lh_Link21.STL"/>
        <mesh name="l_pinky_proximal_col" file="meshes/inspire_hands/lh_Link21.STL"/>
        <mesh name="l_pinky_distal_vis" file="meshes/inspire_hands/lh_Link22.STL"/>
        <mesh name="l_pinky_distal_col" file="meshes/inspire_hands/lh_Link22.STL"/>


        <material name="site_left_hand" rgba="0.1882 0.1882 0.1882 0"/>
        <material name="l_base_material" rgba="0 0 0 1"/>
        <material name="l_thumb_material" rgba="0 0 0 1"/>
        <material name="l_index_material" rgba="0 0 0 1"/>
        <material name="l_middle_material" rgba="0 0 0 1"/>
        <material name="l_ring_material" rgba="0 0 0 1"/>
        <material name="l_pinky_material" rgba="0 0 0 1"/>
        <material name="l_thumb_distal_material" rgba="0 0 0 1"/>

        <mesh name="r_palm_vis" file="meshes/inspire_hands/rh_base_link.STL"/>
        <mesh name="r_palm_col" file="meshes/inspire_hands/rh_base_link.STL"/>
        <mesh name="r_thumb_proximal_1_vis" file="meshes/inspire_hands/rh_Link11.STL"/>
        <mesh name="r_thumb_proximal_1_col" file="meshes/inspire_hands/rh_Link11.STL"/>
        <mesh name="r_thumb_proximal_2_vis" file="meshes/inspire_hands/rh_Link12.STL"/>
        <mesh name="r_thumb_proximal_2_col" file="meshes/inspire_hands/rh_Link12.STL"/>
        <mesh name="r_thumb_middle_vis" file="meshes/inspire_hands/rh_Link13.STL"/>
        <mesh name="r_thumb_middle_col" file="meshes/inspire_hands/rh_Link13.STL"/>
        <mesh name="r_thumb_distal_vis" file="meshes/inspire_hands/rh_Link14.STL"/>
        <mesh name="r_thumb_distal_col" file="meshes/inspire_hands/rh_Link14.STL"/>
        <mesh name="r_index_proximal_vis" file="meshes/inspire_hands/rh_Link15.STL"/>
        <mesh name="r_index_proximal_col" file="meshes/inspire_hands/rh_Link15.STL"/>
        <mesh name="r_index_distal_vis" file="meshes/inspire_hands/rh_Link16.STL"/>
        <mesh name="r_index_distal_col" file="meshes/inspire_hands/rh_Link16.STL"/>
        <mesh name="r_middle_proximal_vis" file="meshes/inspire_hands/rh_Link17.STL"/>
        <mesh name="r_middle_proximal_col" file="meshes/inspire_hands/rh_Link17.STL"/>
        <mesh name="r_middle_distal_vis" file="meshes/inspire_hands/rh_Link18.STL"/>
        <mesh name="r_middle_distal_col" file="meshes/inspire_hands/rh_Link18.STL"/>
        <mesh name="r_ring_proximal_vis" file="meshes/inspire_hands/rh_Link19.STL"/>
        <mesh name="r_ring_proximal_col" file="meshes/inspire_hands/rh_Link19.STL"/>
        <mesh name="r_ring_distal_vis" file="meshes/inspire_hands/rh_Link20.STL"/>
        <mesh name="r_ring_distal_col" file="meshes/inspire_hands/rh_Link20.STL"/>
        <mesh name="r_pinky_proximal_vis" file="meshes/inspire_hands/rh_Link21.STL"/>
        <mesh name="r_pinky_proximal_col" file="meshes/inspire_hands/rh_Link21.STL"/>
        <mesh name="r_pinky_distal_vis" file="meshes/inspire_hands/rh_Link22.STL"/>
        <mesh name="r_pinky_distal_col" file="meshes/inspire_hands/rh_Link22.STL"/>

        <material name="site_right_hand" rgba="0.1882 0.1882 0.1882 0"/>
        <material name="r_base_material" rgba="0 0 0 1"/>
        <material name="r_thumb_material" rgba="0 0 0 1"/>
        <material name="r_index_material" rgba="0 0 0 1"/>
        <material name="r_middle_material" rgba="0 0 0 1"/>
        <material name="r_ring_material" rgba="0 0 0 1"/>
        <material name="r_pinky_material" rgba="0 0 0 1"/>
        <material name="r_thumb_distal_material" rgba="0 0 0 1"/>
    </asset>

    <worldbody>
        <light mode="targetbodycom" target="torso_link" pos="2 0 2.5"/>
        <body name="stand" pos="0 0 0.5">
        <geom type="box" size="0.1 0.1 0.32" rgba="0.5 0.5 0.5 1"/>
        </body>
        <body name="pelvis" pos="0 0 1.06" childclass="h1">
            <inertial pos="-0.0002 4e-05 -0.04522" quat="0.498303 0.499454 -0.500496 0.501741" mass="5.39"
                      diaginertia="0.0490211 0.0445821 0.00824619"/>
<!--            <freejoint/>-->
            <geom class="visual" mesh="pelvis"/>
            <body name="left_hip_yaw_link" pos="0 0.0875 -0.1742">
                <inertial pos="-0.04923 0.0001 0.0072" quat="0.69699 0.219193 0.233287 0.641667" mass="2.244"
                          diaginertia="0.00304494 0.00296885 0.00189201"/>
                <joint name="left_hip_yaw" axis="0 0 1" range="-0.43 0.43"/>
                <geom class="visual" mesh="left_hip_yaw_link"/>
                <geom size="0.06 0.035" pos="-0.067 0 0" quat="0.707123 0 0.70709 0" type="cylinder" class="collision"/>
                <body name="left_hip_roll_link" pos="0.039468 0 0">
                    <inertial pos="-0.0058 -0.00319 -9e-05" quat="0.0438242 0.70721 -0.0729075 0.701867" mass="2.232"
                              diaginertia="0.00243264 0.00225325 0.00205492"/>
                    <joint name="left_hip_roll" axis="1 0 0" range="-0.43 0.43"/>
                    <geom class="visual" mesh="left_hip_roll_link"/>
                    <geom class="collision" type="cylinder" size="0.05 0.03" quat="1 1 0 0" pos="0 -0.02 0"/>
                    <body name="left_hip_pitch_link" pos="0 0.11536 0">
                        <inertial pos="0.00746 -0.02346 -0.08193" quat="0.979828 0.0513522 -0.0169854 -0.192382"
                                  mass="4.152"
                                  diaginertia="0.0829503 0.0821457 0.00510909"/>
                        <joint name="left_hip_pitch" axis="0 1 0" range="-1.57 1.57"/>
                        <geom class="visual" mesh="left_hip_pitch_link"/>
                        <geom class="collision" type="capsule" size="0.03" fromto="0.02 0 -0.4 -0.02 0 0.02"/>
                        <geom class="collision" type="capsule" size="0.03" fromto="0.02 0 -0.4 0.02 0 0.02"/>
                        <geom class="collision" type="cylinder" size="0.05 0.02" quat="1 1 0 0" pos="0 -0.07 0"/>
                        <body name="left_knee_link" pos="0 0 -0.4">
                            <inertial pos="-0.00136 -0.00512 -0.1384" quat="0.626132 -0.034227 -0.0416277 0.777852"
                                      mass="1.721"
                                      diaginertia="0.0125237 0.0123104 0.0019428"/>
                            <joint name="left_knee" axis="0 1 0" range="-0.26 2.05"/>
                            <geom class="visual" mesh="left_knee_link"/>
                            <geom class="collision" type="capsule" size="0.025" fromto="0.02 0 -0.4 0.02 0 0"/>
                            <geom class="collision" type="sphere" size="0.05" pos="0 0 -0.115"/>
                            <body name="left_ankle_link" pos="0 0 -0.4">
                                <inertial pos="0.06722 0.00015 -0.04497" quat="0.489101 0.503197 0.565782 0.432972"
                                          mass="0.446"
                                          diaginertia="0.00220848 0.00218961 0.000214202"/>
                                <joint name="left_ankle" axis="0 1 0" range="-0.87 0.52"/>
                                <geom class="visual" mesh="left_ankle_link"/>
                                <geom class="foot1"/>
                                <geom class="foot2"/>
                                <geom class="foot3"/>
                                <site name="left_foot" pos="0.15 0 -0.05"/>
                            </body>
                        </body>
                    </body>
                </body>
            </body>
            <body name="right_hip_yaw_link" pos="0 -0.0875 -0.1742">
                <inertial pos="-0.04923 -0.0001 0.0072" quat="0.641667 0.233287 0.219193 0.69699" mass="2.244"
                          diaginertia="0.00304494 0.00296885 0.00189201"/>
                <joint name="right_hip_yaw" axis="0 0 1" range="-0.43 0.43"/>
                <geom class="visual" mesh="right_hip_yaw_link"/>
                <geom size="0.06 0.035" pos="-0.067 0 0" quat="0.707123 0 0.70709 0" type="cylinder" class="collision"/>
                <body name="right_hip_roll_link" pos="0.039468 0 0">
                    <inertial pos="-0.0058 0.00319 -9e-05" quat="-0.0438242 0.70721 0.0729075 0.701867" mass="2.232"
                              diaginertia="0.00243264 0.00225325 0.00205492"/>
                    <joint name="right_hip_roll" axis="1 0 0" range="-0.43 0.43"/>
                    <geom class="visual" mesh="right_hip_roll_link"/>
                    <geom class="collision" type="cylinder" size="0.05 0.03" quat="1 1 0 0" pos="0 0.02 0"/>
                    <body name="right_hip_pitch_link" pos="0 -0.11536 0">
                        <inertial pos="0.00746 0.02346 -0.08193" quat="0.979828 -0.0513522 -0.0169854 0.192382"
                                  mass="4.152"
                                  diaginertia="0.0829503 0.0821457 0.00510909"/>
                        <joint name="right_hip_pitch" axis="0 1 0" range="-1.57 1.57"/>
                        <geom class="visual" mesh="right_hip_pitch_link"/>
                        <geom class="collision" type="capsule" size="0.03" fromto="0.02 0 -0.4 -0.02 0 0.02"/>
                        <geom class="collision" type="capsule" size="0.03" fromto="0.02 0 -0.4 0.02 0 0.02"/>
                        <geom class="collision" type="cylinder" size="0.05 0.02" quat="1 1 0 0" pos="0 0.07 0"/>
                        <body name="right_knee_link" pos="0 0 -0.4">
                            <inertial pos="-0.00136 0.00512 -0.1384" quat="0.777852 -0.0416277 -0.034227 0.626132"
                                      mass="1.721"
                                      diaginertia="0.0125237 0.0123104 0.0019428"/>
                            <joint name="right_knee" axis="0 1 0" range="-0.26 2.05"/>
                            <geom class="visual" mesh="right_knee_link"/>
                            <geom class="collision" type="capsule" size="0.025" fromto="0.02 0 -0.4 0.02 0 0"/>
                            <geom class="collision" type="sphere" size="0.05" pos="0 0 -0.115"/>
                            <body name="right_ankle_link" pos="0 0 -0.4">
                                <inertial pos="0.06722 -0.00015 -0.04497" quat="0.432972 0.565782 0.503197 0.489101"
                                          mass="0.446"
                                          diaginertia="0.00220848 0.00218961 0.000214202"/>
                                <joint name="right_ankle" axis="0 1 0" range="-0.87 0.52"/>
                                <geom class="visual" mesh="right_ankle_link"/>
                                <geom class="foot1"/>
                                <geom class="foot2"/>
                                <geom class="foot3"/>
                                <site name="right_foot" pos="0.15 0 -0.05"/>
                            </body>
                        </body>
                    </body>
                </body>
            </body>
            <body name="torso_link">
                <inertial pos="0.000489 0.002797 0.20484" quat="0.999989 -0.00130808 -0.00282289 -0.00349105"
                          mass="17.789"
                          diaginertia="0.487315 0.409628 0.127837"/>
                <joint name="torso" axis="0 0 1" range="-2.35 2.35"/>
                <geom class="visual" mesh="torso_link"/>
                <geom class="visual" material="white" mesh="logo_link"/>
                <geom name="head" class="collision" type="capsule" size="0.06" fromto="0.05 0 0.68 0.05 0 0.6"/>
                
                <camera name="head_camera" mode="fixed" pos="0 0 0.68" ipd="0.068" euler="0 0 0"/>

                <geom name="helmet" class="collision" type="sphere" size="0.073" pos="0.045 0 0.68"/>
                <geom name="torso" class="collision" type="box" size="0.07 0.1 0.22" pos="0 0 0.25"/>
                <geom name="hip" class="collision" type="capsule" size="0.05" fromto="0 -0.1 -0.05 0 0.1 -0.05"/>
                <site name="imu" pos="-0.04452 -0.01891 0.27756"/>
                <body name="left_shoulder_pitch_link" pos="0.0055 0.15535 0.42999" quat="0.976296 0.216438 0 0">
                    <inertial pos="0.005045 0.053657 -0.015715" quat="0.814858 0.579236 -0.0201072 -0.00936488"
                              mass="1.033"
                              diaginertia="0.00129936 0.000987113 0.000858198"/>
                    <joint name="left_shoulder_pitch" axis="0 1 0" range="-2.87 2.87"/>
                    <geom class="visual" mesh="left_shoulder_pitch_link"/>
                    <body name="left_shoulder_roll_link" pos="-0.0055 0.0565 -0.0165" quat="0.976296 -0.216438 0 0">
                        <inertial pos="0.000679 0.00115 -0.094076" quat="0.732491 0.00917179 0.0766656 0.676384"
                                  mass="0.793"
                                  diaginertia="0.00170388 0.00158256 0.00100336"/>
                        <joint name="left_shoulder_roll" axis="1 0 0" range="-0.34 3.11"/>
                        <geom class="visual" mesh="left_shoulder_roll_link"/>
                        <geom name="left_shoulder" class="collision" type="capsule" size="0.04"
                              fromto="0 0.01 0.008 0 -0.07 -0.02"/>
                        <body name="left_shoulder_yaw_link" pos="0 0 -0.1343">
                            <inertial pos="0.01365 0.002767 -0.16266" quat="0.703042 -0.0331229 -0.0473362 0.708798"
                                      mass="0.839"
                                      diaginertia="0.00408038 0.00370367 0.000622687"/>
                            <joint name="left_shoulder_yaw" axis="0 0 1" range="-1.3 4.45"/>
                            <geom class="visual" mesh="left_shoulder_yaw_link"/>
                            <geom class="collision" type="capsule" size="0.03" fromto="0 0 0.15 0 0 -0.2"/>
                            <body name="left_elbow_link" pos="0.0185 0 -0.198">
                                <inertial pos="0.15908 -0.000144 -0.015776" quat="0.0765232 0.720327 0.0853116 0.684102"
                                          mass="0.669"
                                          diaginertia="0.00601829 0.00600579 0.000408305"/>
                                <joint name="left_elbow" axis="0 1 0" range="-1.25 2.61"/>
                                <geom class="visual" mesh="left_elbow_link"/>
                                <geom class="collision" type="capsule" size="0.025" fromto="0 0 0 0.28 0 -0.015"/>
                                <geom class="collision" type="sphere" size="0.033" pos="0.28 0 -0.015"/>
                                <site name="left_wrist" pos="0.2605 0 -0.0185"/>
                                <body name="left_hand" pos="0.2605 0 -0.0185" quat="0.707 0 0 0.707">
                                    <site name="left_ft_frame" pos="0 0 0" size="0.01 0.01 0.01" rgba="1 0 0 0"
                                          type="sphere"
                                          group="1"/>
                                    <inertial diaginertia="0 0 0" mass="0" pos="0 0 0"/>
                                    <body name="left_eef" pos="0 0 0" quat="0.707 0. -0.707 0.">
                                        <!-- <site name="left_grip_site" pos="0 -0.08 0.02" size="0.01 0.01 0.01" rgba="1 1 0 1"
                                              type="sphere" group="2"/> -->
                                        <site name="left_ee_x" pos="0.1 0 0" size="0.005 .1"
                                              quat="0.707105  0 0.707108 0 "
                                              rgba="1 0 0 0" type="cylinder" group="1"/>
                                        <site name="left_ee_y" pos="0 0.1 0" size="0.005 .1"
                                              quat="0.707105 0.707108 0 0"
                                              rgba="0 1 0 0" type="cylinder" group="1"/>
                                        <site name="left_ee_z" pos="0 0 0.1" size="0.005 .1" quat="1 0 0 0"
                                              rgba="0 0 1 0"
                                              type="cylinder" group="1"/>
                                        <!-- This site was added for visualization. -->
<!--                                        <site name="left_grip_site_cylinder" pos="0 0 0" quat="-0.5 -0.5 -0.5 0.5"-->
<!--                                              size="0.005 0.5" rgba="0 1 0 0.3" type="cylinder" group="1"/>-->
                                    </body>


                                    <!-- Palm  -->
                                    <body name="l_palm" pos="0 0 0">
                                        <!-- Palm Visual -->
                                        <geom name="l_palm_vis" type="mesh" mesh="l_palm_vis" material="l_base_material"
                                              group="1" contype="0" conaffinity="0"/>
                                        <!-- Palm Collision -->
                                        <geom name="l_palm_col" type="mesh" mesh="l_palm_col" mass="0.1"/>

                                        <!-- Thumb -->
                                        <body name="l_thumb" pos="0. 0. 0.">
                                            <!-- Thumb Proximal 1 -->
                                            <body name="l_thumb_proximal_1" pos="-0.01496 -0.0375 0.02045"
                                                  quat="0.5 0.5 -0.5 0.5">
                                                <joint name="joint_l_thumb_proximal_1" type="hinge" pos="0 0 0"
                                                       axis="0 0 1" range="0 1.30" limited="true" damping="0.5"/>
                                                <geom name="l_thumb_proximal_vis" type="mesh"
                                                      mesh="l_thumb_proximal_1_vis" material="l_thumb_material"
                                                      group="1" contype="0" conaffinity="0"></geom>
                                                <geom name="l_thumb_proximal_col" type="mesh"
                                                      mesh="l_thumb_proximal_1_col" mass="0.1"/>

                                                <!-- Thumb Proximal 2 -->
                                                <body name="l_thumb_proximal_2" pos="0.0099867 0.0098242 -0.0089"
                                                      quat="0.705 -0.705 -0.060 0.060">
                                                    <joint name="joint_l_thumb_proximal_2" type="hinge" pos="0 0 0"
                                                           axis="0 0 -1" range="0 0.68" limited="true" damping="0.5"/>
                                                    <geom name="l_thumb_proximal_2_vis" type="mesh"
                                                          mesh="l_thumb_proximal_2_vis" material="l_thumb_material"
                                                          group="1" contype="0" conaffinity="0"></geom>
                                                    <geom name="l_thumb_proximal_2_col" type="mesh"
                                                          mesh="l_thumb_proximal_2_col" mass="0.1"/>

                                                    <site name="site_l_thumb_proximal_2" size="0.01"
                                                          material="site_left_hand"/>

                                                    <!-- Thumb Middle -->
                                                    <body name="l_thumb_middle" pos="0.04407 -0.034553 -0.0008"
                                                          quat="1 0 0 0">
                                                        <joint name="joint_l_thumb_middle" type="hinge" pos="0 0 0"
                                                               axis="0 0 -1" range="0 0.68" limited="true" damping="0.5"/>
                                                        <geom name="l_thumb_middle_vis" type="mesh"
                                                              mesh="l_thumb_middle_vis" material="l_thumb_material"
                                                              group="1" contype="0" conaffinity="0"/>
                                                        <geom name="l_thumb_middle_col" type="mesh"
                                                              mesh="l_thumb_middle_col" mass="0.1"/>
                                                        <site name="site_l_thumb_middle" size="0.01"
                                                              material="site_left_hand"/>

                                                        <!-- Thumb Distal -->
                                                        <body name="l_thumb_distal" pos="0.020248 -0.010156 -0.0012"
                                                              quat="1 0 0 0">
                                                            <joint name="joint_l_thumb_distal" type="hinge" pos="0 0 0"
                                                                   axis="0 0 -1" range="0 0.77" limited="true"
                                                                   damping="0.5"/>
                                                            <geom name="l_thumb_distal_vis" type="mesh"
                                                                  mesh="l_thumb_distal_vis"
                                                                  material="l_thumb_distal_material" group="1"
                                                                  contype="0" conaffinity="0"></geom>
                                                            <geom name="l_thumb_distal_col" type="mesh"
                                                                  mesh="l_thumb_distal_col" mass="0.1"/>
                                                            <site name="site_l_thumb_distal" size="0.01"
                                                                  material="site_left_hand"/>
                                                        </body>
                                                        <!-- End of Thumb Distal -->
                                                    </body>
                                                    <!-- End of Thumb Middle -->
                                                </body>
                                                <!-- End of Thumb Proximal 2 -->
                                            </body>
                                            <!-- End of Thumb Proximal 1 -->
                                        </body>
                                        <!-- End of Thumb -->

                                        <!-- Index finger -->
                                        <body name="l_index" pos="0 0 0">
                                            <!-- Index Proximal -->
                                            <body name="l_index_proximal" pos="0.0022853 -0.10493 0.032268"
                                                  quat="0.99985 -0.01745 0.0 0.0">
                                                <joint name="joint_l_index_proximal" type="hinge" pos="0 0 0"
                                                       axis="0 0 -1" range="0 1.62" limited="true" damping="0.5"/>
                                                <site name="site_l_index_proximal" size="0.01"
                                                      material="site_left_hand"/>
                                                <geom name="l_index_proximal_vis" type="mesh"
                                                      mesh="l_index_proximal_vis" material="l_index_material" group="1"
                                                      contype="0" conaffinity="0"/>
                                                <geom name="l_index_proximal_col" type="mesh"
                                                      mesh="l_index_proximal_col" mass="0.1"/>
                                                <!-- Index Distal -->
                                                <body name="l_index_distal" pos="-0.0024229 -0.032041 -0.001"
                                                      quat="1 0 0 0">
                                                    <joint name="joint_l_index_distal" type="hinge" pos="0 0 0"
                                                           axis="0 0 -1" range="0 1.82" limited="true" damping="0.5"/>
                                                    <site name="site_l_index_distal" size="0.01"
                                                          material="site_left_hand"/>
                                                    <geom name="l_index_distal_vis" type="mesh"
                                                          mesh="l_index_distal_vis" material="l_index_material"
                                                          group="1" contype="0" conaffinity="0"/>
                                                    <geom name="l_index_distal_col" type="mesh"
                                                          mesh="l_index_distal_col" mass="0.1"/>
                                                </body>
                                                <!-- End of Index Distal -->
                                            </body>
                                            <!-- End of Index Proximal -->
                                        </body>
                                        <!-- End of Index finger -->
                                        <!-- Middle finger -->
                                        <body name="l_middle" pos="0 0 0">
                                            <!-- Middle Proximal -->
                                            <body name="l_middle_proximal" pos="0.0022853 -0.1055 0.01295"
                                                  quat="1 0 0 0">
                                                <joint name="joint_l_middle_proximal" type="hinge" pos="0 0 0"
                                                       axis="0 0 -1" range="0 1.62" limited="true" damping="0.5"/>
                                                <site name="site_l_middle_proximal" size="0.01"
                                                      material="site_left_hand"/>
                                                <geom name="l_middle_proximal_vis" type="mesh"
                                                      mesh="l_middle_proximal_vis" material="l_middle_material"
                                                      group="1" contype="0" conaffinity="0"/>
                                                <geom name="l_middle_proximal_col" type="mesh"
                                                      mesh="l_middle_proximal_col" mass="0.1"/>
                                                <!-- Middle Distal -->
                                                <body name="l_middle_distal" pos="-0.0024229 -0.032041 -0.001"
                                                      quat="1 0 0 0">
                                                    <joint name="joint_l_middle_distal" type="hinge" pos="0 0 0"
                                                           axis="0 0 -1" range="0 1.82" limited="true" damping="0.5"/>
                                                    <site name="site_l_middle_distal" size="0.01"
                                                          material="site_left_hand"/>
                                                    <geom name="l_middle_distal_vis" type="mesh"
                                                          mesh="l_middle_distal_vis" material="l_middle_material"
                                                          group="1" contype="0" conaffinity="0"/>
                                                    <geom name="l_middle_distal_col" type="mesh"
                                                          mesh="l_middle_distal_col" mass="0.1"/>
                                                </body>
                                                <!-- End of Middle Distal -->
                                            </body>
                                            <!-- End of Middle Proximal -->
                                        </body>
                                        <!-- End of Middle finger -->

                                        <!-- Ring finger -->
                                        <body name="l_ring" pos="0 0 0">
                                            <!-- Ring Proximal -->
                                            <body name="l_ring_proximal" pos="0.0022853 -0.10531 -0.0062872"
                                                  quat="0.99966 0.02618 0.0 0.0">
                                                <joint name="joint_l_ring_proximal" type="hinge" pos="0 0 0"
                                                       axis="0 0 -1" range="0 1.62" limited="true" damping="0.5"/>
                                                <site name="site_l_ring_proximal" size="0.01"
                                                      material="site_left_hand"/>
                                                <geom name="l_ring_proximal_vis" type="mesh" mesh="l_ring_proximal_vis"
                                                      material="l_ring_material" group="1" contype="0" conaffinity="0"/>
                                                <geom name="l_ring_proximal_col" type="mesh" mesh="l_ring_proximal_col"
                                                      mass="0.1"/>
                                                <!-- Ring Distal -->
                                                <body name="l_ring_distal" pos="-0.0024229 -0.032041 -0.001"
                                                      quat="1 0 0 0">
                                                    <joint name="joint_l_ring_distal" type="hinge" pos="0 0 0"
                                                           axis="0 0 -1" range="0 1.75" limited="true" damping="0.5"/>
                                                    <site name="site_l_ring_distal" size="0.01"
                                                          material="site_left_hand"/>
                                                    <geom name="l_ring_distal_vis" type="mesh" mesh="l_ring_distal_vis"
                                                          material="l_ring_material" group="1" contype="0"
                                                          conaffinity="0"/>
                                                    <geom name="l_ring_distal_col" type="mesh" mesh="l_ring_distal_col"
                                                          mass="0.1"/>
                                                </body>
                                                <!-- End of Ring Distal -->
                                            </body>
                                            <!-- End of Ring Proximal -->
                                        </body>
                                        <!-- End of Ring finger -->

                                        <!-- Pinky finger -->
                                        <body name="l_pinky" pos="0 0 0">
                                            <!-- Pinky Proximal -->
                                            <body name="l_pinky_proximal" pos="0.0022853 -0.10411 -0.025488"
                                                  quat="0.99863 0.05234 0.0 0.0">
                                                <joint name="joint_l_pinky_proximal" type="hinge" pos="0 0 0"
                                                       axis="0 0 -1" range="0 1.62" limited="true" damping="0.5"/>
                                                <site name="site_l_pinky_proximal" size="0.01"
                                                      material="site_left_hand"/>
                                                <geom name="l_pinky_proximal_vis" type="mesh"
                                                      mesh="l_pinky_proximal_vis" material="l_pinky_material" group="1"
                                                      contype="0" conaffinity="0"/>
                                                <geom name="l_pinky_proximal_col" type="mesh"
                                                      mesh="l_pinky_proximal_col" mass="0.1"/>
                                                <!-- Pinky Distal -->
                                                <body name="l_pinky_distal" pos="-0.0024229 -0.032041 -0.001"
                                                      quat="1 0 0 0">
                                                    <joint name="joint_l_pinky_distal" type="hinge" pos="0 0 0"
                                                           axis="0 0 -1" range="0 1.87" limited="true" damping="0.5"/>
                                                    <site name="site_l_pinky_distal" size="0.01"
                                                          material="site_left_hand"/>
                                                    <geom name="l_pinky_distal_vis" type="mesh"
                                                          mesh="l_pinky_distal_vis" material="l_pinky_material"
                                                          group="1" contype="0" conaffinity="0"/>
                                                    <geom name="l_pinky_distal_col" type="mesh"
                                                          mesh="l_pinky_distal_col" mass="0.1"/>
                                                </body>
                                                <!-- End of Pinky Distal -->
                                            </body>
                                            <!-- End of Pinky Proximal -->
                                        </body>
                                        <!-- End of Pinky finger -->

                                    </body>
                                    <!-- End of Palm -->
                                </body>
                            </body>
                        </body>
                    </body>
                </body>
                <body name="right_shoulder_pitch_link" pos="0.0055 -0.15535 0.42999" quat="0.976296 -0.216438 0 0">
                    <inertial pos="0.005045 -0.053657 -0.015715" quat="0.579236 0.814858 0.00936488 0.0201072"
                              mass="1.033"
                              diaginertia="0.00129936 0.000987113 0.000858198"/>
                    <joint name="right_shoulder_pitch" axis="0 1 0" range="-2.87 2.87"/>
                    <geom class="visual" mesh="right_shoulder_pitch_link"/>
                    <body name="right_shoulder_roll_link" pos="-0.0055 -0.0565 -0.0165" quat="0.976296 0.216438 0 0">
                        <inertial pos="0.000679 -0.00115 -0.094076" quat="0.676384 0.0766656 0.00917179 0.732491"
                                  mass="0.793"
                                  diaginertia="0.00170388 0.00158256 0.00100336"/>
                        <joint name="right_shoulder_roll" axis="1 0 0" range="-3.11 0.34"/>
                        <geom class="visual" mesh="right_shoulder_roll_link"/>
                        <geom name="right_shoulder" class="collision" type="capsule" size="0.04"
                              fromto="0 -0.01 0.008 0 0.07 -0.02"/>
                        <body name="right_shoulder_yaw_link" pos="0 0 -0.1343">
                            <inertial pos="0.01365 -0.002767 -0.16266" quat="0.708798 -0.0473362 -0.0331229 0.703042"
                                      mass="0.839"
                                      diaginertia="0.00408038 0.00370367 0.000622687"/>
                            <joint name="right_shoulder_yaw" axis="0 0 1" range="-4.45 1.3"/>
                            <geom class="visual" mesh="right_shoulder_yaw_link"/>
                            <geom class="collision" type="capsule" size="0.03" fromto="0 0 0.15 0 0 -0.2"/>
                            <body name="right_elbow_link" pos="0.0185 0 -0.198">
                                <inertial pos="0.15908 0.000144 -0.015776"
                                          quat="-0.0765232 0.720327 -0.0853116 0.684102" mass="0.669"
                                          diaginertia="0.00601829 0.00600579 0.000408305"/>
                                <joint name="right_elbow" axis="0 1 0" range="-1.25 2.61"/>
                                <geom class="visual" mesh="right_elbow_link"/>
                                <geom class="collision" type="capsule" size="0.025" fromto="0 0 0 0.28 0 -0.015"/>
                                <geom class="collision" type="sphere" size="0.033" pos="0.28 0 -0.015"/>
                                <site name="right_wrist" pos="0.2605 0 -0.0185"/>
                                <body name="right_hand" pos="0.2605 0 -0.0185" quat="0 0.707 -0.707 0">
                                    <site name="right_ft_frame" pos="0 0 0" size="0.01 0.01 0.01" rgba="1 0 0 0"
                                          type="sphere"
                                          group="1"/>
                                    <inertial diaginertia="0 0 0" mass="0" pos="0 0 0"/>
                                    <body name="right_eef" pos="0 0 0" quat="0.707 0. -0.707 0.">
                                        <!-- <site name="right_grip_site" pos="0 -0.08 0.02" size="0.01 0.01 0.01" rgba="1 1 0 1"
                                              type="sphere" group="2"/> -->
                                        <site name="right_ee_x" pos="0.1 0 0" size="0.005 .1"
                                              quat="0.707105  0 0.707108 0 "
                                              rgba="1 0 0 0" type="cylinder" group="1"/>
                                        <site name="right_ee_y" pos="0 0.1 0" size="0.005 .1"
                                              quat="0.707105 0.707108 0 0"
                                              rgba="0 1 0 0" type="cylinder" group="1"/>
                                        <site name="right_ee_z" pos="0 0 0.1" size="0.005 .1" quat="1 0 0 0"
                                              rgba="0 0 1 0"
                                              type="cylinder" group="1"/>
                                        <!-- This site was added for visualization. -->
<!--                                        <site name="right_grip_site_cylinder" pos="0 0 0" quat="-0.5 -0.5 -0.5 0.5"-->
<!--                                              size="0.005 0.5" rgba="0 1 0 0.3" type="cylinder" group="1"/>-->
                                    </body>


                                    <!-- Palm  -->
                                    <body name="r_palm" pos="0 0 0">
                                        <!-- Palm Visual -->
                                        <geom name="r_palm_vis" type="mesh" mesh="r_palm_vis" material="r_base_material"
                                              group="1" contype="0" conaffinity="0"/>
                                        <!-- Palm Collision -->
                                        <geom name="r_palm_col" type="mesh" mesh="r_palm_col" mass="0.1"/>

                                        <!-- Thumb -->
                                        <body name="r_thumb" pos="0. 0. 0.">
                                            <!-- Thumb Proximal 1 -->
                                            <body name="r_thumb_proximal_1" pos="-0.01496 -0.0375 -0.02045"
                                                  quat="0.5 0.5 -0.5 0.5">
                                                <joint name="joint_r_thumb_proximal_1" type="hinge" pos="0 0 0"
                                                       axis="0 0 -1" range="0 1.30" limited="true" damping="0.5"/>
                                                <geom name="r_thumb_proximal_vis" type="mesh"
                                                      mesh="r_thumb_proximal_1_vis" material="r_thumb_material"
                                                      group="1" contype="0" conaffinity="0"></geom>
                                                <geom name="r_thumb_proximal_col" type="mesh"
                                                      mesh="r_thumb_proximal_1_col" mass="0.1"/>

                                                <!-- Thumb Proximal 2 -->
                                                <body name="r_thumb_proximal_2" pos="-0.0088099 0.010892 -0.00925"
                                                      quat="0.1 0.1 0.7 0.7">
                                                    <joint name="joint_r_thumb_proximal_2" type="hinge" pos="0 0 0"
                                                           axis="0 0 1" range="0 0.68" limited="true" damping="0.5"/>
                                                    <geom name="r_thumb_proximal_2_vis" type="mesh"
                                                          mesh="r_thumb_proximal_2_vis" material="r_thumb_material"
                                                          group="1" contype="0" conaffinity="0"></geom>
                                                    <geom name="r_thumb_proximal_2_col" type="mesh"
                                                          mesh="r_thumb_proximal_2_col" mass="0.1"/>

                                                    <site name="site_r_thumb_proximal_2" size="0.01"
                                                          material="site_right_hand"/>

                                                    <!-- Thumb Middle -->
                                                    <body name="r_thumb_middle" pos="0.04407 0.034553 -0.0008"
                                                          quat="1 0 0 0">
                                                        <joint name="joint_r_thumb_middle" type="hinge" pos="0 0 0"
                                                               axis="0 0 1" range="0 0.68" limited="true" damping="0.5"/>
                                                        <geom name="r_thumb_middle_vis" type="mesh"
                                                              mesh="r_thumb_middle_vis" material="r_thumb_material"
                                                              group="1" contype="0" conaffinity="0"/>
                                                        <geom name="r_thumb_middle_col" type="mesh"
                                                              mesh="r_thumb_middle_col" mass="0.1"/>
                                                        <site name="site_r_thumb_middle" size="0.01"
                                                              material="site_right_hand"/>

                                                        <!-- Thumb Distal -->
                                                        <body name="r_thumb_distal" pos="0.020248 0.010156 -0.0012"
                                                              quat="1 0 0 0">
                                                            <joint name="joint_r_thumb_distal" type="hinge" pos="0 0 0"
                                                                   axis="0 0 1" range="0 0.77" limited="true"
                                                                   damping="0.5"/>
                                                            <geom name="r_thumb_distal_vis" type="mesh"
                                                                  mesh="r_thumb_distal_vis"
                                                                  material="r_thumb_distal_material" group="1"
                                                                  contype="0" conaffinity="0"></geom>
                                                            <geom name="r_thumb_distal_col" type="mesh"
                                                                  mesh="r_thumb_distal_col" mass="0.1"/>
                                                            <site name="site_r_thumb_distal" size="0.01"
                                                                  material="site_right_hand"/>
                                                        </body>
                                                        <!-- End of Thumb Distal -->
                                                    </body>
                                                    <!-- End of Thumb Middle -->
                                                </body>
                                                <!-- End of Thumb Proximal 2 -->
                                            </body>
                                            <!-- End of Thumb Proximal 1 -->
                                        </body>
                                        <!-- End of Thumb -->

                                        <!-- Index finger -->
                                        <body name="r_index" pos="0 0 0">
                                            <!-- Index Proximal -->
                                            <body name="r_index_proximal" pos="0.0022853 -0.10493 -0.032268"
                                                  quat="0.01745 -0.99985 0.0 0.0">
                                                <joint name="joint_r_index_proximal" type="hinge" pos="0 0 0"
                                                       axis="0 0 1" range="0 1.62" limited="true" damping="0.5"/>
                                                <site name="site_r_index_proximal" size="0.01"
                                                      material="site_right_hand"/>
                                                <geom name="r_index_proximal_vis" type="mesh"
                                                      mesh="r_index_proximal_vis" material="r_index_material" group="1"
                                                      contype="0" conaffinity="0"/>
                                                <geom name="r_index_proximal_col" type="mesh"
                                                      mesh="r_index_proximal_col" mass="0.1"/>
                                                <!-- Index Distal -->
                                                <body name="r_index_distal" pos="-0.0026138 0.032026 -0.001"
                                                      quat="1 0 0 0">
                                                    <joint name="joint_r_index_distal" type="hinge" pos="0 0 0"
                                                           axis="0 0 1" range="0 1.82" limited="true" damping="0.5"/>
                                                    <site name="site_r_index_distal" size="0.01"
                                                          material="site_right_hand"/>
                                                    <geom name="r_index_distal_vis" type="mesh"
                                                          mesh="r_index_distal_vis" material="r_index_material"
                                                          group="1" contype="0" conaffinity="0"/>
                                                    <geom name="r_index_distal_col" type="mesh"
                                                          mesh="r_index_distal_col" mass="0.1"/>
                                                </body>
                                                <!-- End of Index Distal -->
                                            </body>
                                            <!-- End of Index Proximal -->
                                        </body>
                                        <!-- End of Index finger -->
                                        <!-- Middle finger -->
                                        <body name="r_middle" pos="0 0 0">
                                            <!-- Middle Proximal -->
                                            <body name="r_middle_proximal" pos="0.0022853 -0.1055 -0.01295"
                                                  quat="0 -1 0.0 0.0">
                                                <joint name="joint_r_middle_proximal" type="hinge" pos="0 0 0"
                                                       axis="0 0 1" range="0 1.62" limited="true" damping="0.5"/>
                                                <site name="site_r_middle_proximal" size="0.01"
                                                      material="site_right_hand"/>
                                                <geom name="r_middle_proximal_vis" type="mesh"
                                                      mesh="r_middle_proximal_vis" material="r_middle_material"
                                                      group="1" contype="0" conaffinity="0"/>
                                                <geom name="r_middle_proximal_col" type="mesh"
                                                      mesh="r_middle_proximal_col" mass="0.1"/>
                                                <!-- Middle Distal -->
                                                <body name="r_middle_distal" pos="-0.0024229 0.032041 -0.001"
                                                      quat="1 0 0 0">
                                                    <joint name="joint_r_middle_distal" type="hinge" pos="0 0 0"
                                                           axis="0 0 1" range="0 1.82" limited="true" damping="0.5"/>
                                                    <site name="site_r_middle_distal" size="0.01"
                                                          material="site_right_hand"/>
                                                    <geom name="r_middle_distal_vis" type="mesh"
                                                          mesh="r_middle_distal_vis" material="r_middle_material"
                                                          group="1" contype="0" conaffinity="0"/>
                                                    <geom name="r_middle_distal_col" type="mesh"
                                                          mesh="r_middle_distal_col" mass="0.1"/>
                                                </body>
                                                <!-- End of Middle Distal -->
                                            </body>
                                            <!-- End of Middle Proximal -->
                                        </body>
                                        <!-- End of Middle finger -->

                                        <!-- Ring finger -->
                                        <body name="r_ring" pos="0 0 0">
                                            <!-- Ring Proximal -->
                                            <body name="r_ring_proximal" pos="0.0022853 -0.10531 0.0062872"
                                                  quat="0.02619 0.99966 0.0 0.0">
                                                <joint name="joint_r_ring_proximal" type="hinge" pos="0 0 0"
                                                       axis="0 0 1" range="0 1.62" limited="true" damping="0.5"/>
                                                <site name="site_r_ring_proximal" size="0.01"
                                                      material="site_right_hand"/>
                                                <geom name="r_ring_proximal_vis" type="mesh" mesh="r_ring_proximal_vis"
                                                      material="r_ring_material" group="1" contype="0" conaffinity="0"/>
                                                <geom name="r_ring_proximal_col" type="mesh" mesh="r_ring_proximal_col"
                                                      mass="0.1"/>
                                                <!-- Ring Distal -->
                                                <body name="r_ring_distal" pos="-0.0024229 0.032041 -0.001"
                                                      quat="1 0 0 0">
                                                    <joint name="joint_r_ring_distal" type="hinge" pos="0 0 0"
                                                           axis="0 0 1" range="0 1.75" limited="true" damping="0.5"/>
                                                    <site name="site_r_ring_distal" size="0.01"
                                                          material="site_right_hand"/>
                                                    <geom name="r_ring_distal_vis" type="mesh" mesh="r_ring_distal_vis"
                                                          material="r_ring_material" group="1" contype="0"
                                                          conaffinity="0"/>
                                                    <geom name="r_ring_distal_col" type="mesh" mesh="r_ring_distal_col"
                                                          mass="0.1"/>
                                                </body>
                                                <!-- End of Ring Distal -->
                                            </body>
                                            <!-- End of Ring Proximal -->
                                        </body>
                                        <!-- End of Ring finger -->

                                        <!-- Pinky finger -->
                                        <body name="r_pinky" pos="0 0 0">
                                            <!-- Pinky Proximal -->
                                            <body name="r_pinky_proximal" pos="0.0022853 -0.10411 0.025488"
                                                  quat="0.05232 0.99863 0.0 0.0">
                                                <joint name="joint_r_pinky_proximal" type="hinge" pos="0 0 0"
                                                       axis="0 0 1" range="0 1.62" limited="true" damping="0.5"/>
                                                <site name="site_r_pinky_proximal" size="0.01"
                                                      material="site_right_hand"/>
                                                <geom name="r_pinky_proximal_vis" type="mesh"
                                                      mesh="r_pinky_proximal_vis" material="r_pinky_material" group="1"
                                                      contype="0" conaffinity="0"/>
                                                <geom name="r_pinky_proximal_col" type="mesh"
                                                      mesh="r_pinky_proximal_col" mass="0.1"/>
                                                <!-- Pinky Distal -->
                                                <body name="r_pinky_distal" pos="-0.0024229 0.032041 -0.001"
                                                      quat="1 0 0 0">
                                                    <joint name="joint_r_pinky_distal" type="hinge" pos="0 0 0"
                                                           axis="0 0 1" range="0 1.87" limited="true" damping="0.5"/>
                                                    <site name="site_r_pinky_distal" size="0.01"
                                                          material="site_right_hand"/>
                                                    <geom name="r_pinky_distal_vis" type="mesh"
                                                          mesh="r_pinky_distal_vis" material="r_pinky_material"
                                                          group="1" contype="0" conaffinity="0"/>
                                                    <geom name="r_pinky_distal_col" type="mesh"
                                                          mesh="r_pinky_distal_col" mass="0.1"/>
                                                </body>
                                                <!-- End of Pinky Distal -->
                                            </body>
                                            <!-- End of Pinky Proximal -->
                                        </body>
                                        <!-- End of Pinky finger -->

                                    </body>
                                    <!-- End of Palm -->
                                </body>
                            </body>
                        </body>
                    </body>
                </body>
            </body>
        </body>
    </worldbody>

    <contact>
        <exclude body1="torso_link" body2="left_shoulder_roll_link"/>
        <exclude body1="torso_link" body2="right_shoulder_roll_link"/>
        <exclude name="exclude_lh_palm_thumb_proximal_1" body1="l_thumb_proximal_1" body2="l_palm"/>
        <exclude name="exclude_lh_palm_thumb_proximal_1_proximal_2" body1="l_thumb_proximal_1"
                 body2="l_thumb_proximal_2"/>
        <exclude name="exclude_lh_palm_thumb_proximal_2" body1="l_thumb_proximal_2" body2="l_palm"/>
        <exclude name="exclude_lh_palm_thumb_middle_2" body1="l_thumb_middle" body2="l_palm"/>
        <exclude name="exclude_lh_thumb_proximal_2_middle" body1="l_thumb_proximal_2" body2="l_thumb_middle"/>
        <exclude name="exclude_lh_thumb_middle_distal" body1="l_thumb_middle" body2="l_thumb_distal"/>
        <exclude name="exclude_lh_palm_index_proximal" body1="l_index_proximal" body2="l_palm"/>
        <exclude name="exclude_lh_palm_middle_proximal" body1="l_middle_proximal" body2="l_palm"/>
        <exclude name="exclude_lh_palm_ring_proximal" body1="l_ring_proximal" body2="l_palm"/>
        <exclude name="exclude_lh_palm_pinky_proximal" body1="l_pinky_proximal" body2="l_palm"/>
        <exclude name="exclude_rh_palm_thumb_proximal_1" body1="r_thumb_proximal_1" body2="r_palm"/>
        <exclude name="exclude_rh_palm_thumb_proximal_1_proximal_2" body1="r_thumb_proximal_1"
                 body2="r_thumb_proximal_2"/>
        <exclude name="exclude_rh_palm_thumb_proximal_2" body1="r_thumb_proximal_2" body2="r_palm"/>
        <exclude name="exclude_rh_palm_thumb_middle_2" body1="r_thumb_middle" body2="r_palm"/>
        <exclude name="exclude_rh_thumb_proximal_2_middle" body1="r_thumb_proximal_2" body2="r_thumb_middle"/>
        <exclude name="exclude_rh_thumb_middle_distal" body1="r_thumb_middle" body2="r_thumb_distal"/>
        <exclude name="exclude_rh_palm_index_proximal" body1="r_index_proximal" body2="r_palm"/>
        <exclude name="exclude_rh_palm_middle_proximal" body1="r_middle_proximal" body2="r_palm"/>
        <exclude name="exclude_rh_palm_ring_proximal" body1="r_ring_proximal" body2="r_palm"/>
        <exclude name="exclude_rh_palm_pinky_proximal" body1="r_pinky_proximal" body2="r_palm"/>
    </contact>

    <actuator>
        <motor class="h1" name="left_hip_yaw" joint="left_hip_yaw" ctrllimited="true" ctrlrange="-200 200"/>
        <motor class="h1" name="left_hip_roll" joint="left_hip_roll" ctrllimited="true" ctrlrange="-200 200"/>
        <motor class="h1" name="left_hip_pitch" joint="left_hip_pitch" ctrllimited="true" ctrlrange="-200 200"/>
        <motor class="h1" name="left_knee" joint="left_knee" ctrllimited="true" ctrlrange="-300 300"/>
        <motor class="h1" name="left_ankle" joint="left_ankle" ctrllimited="true" ctrlrange="-40 40"/>

        <motor class="h1" name="right_hip_yaw" joint="right_hip_yaw" ctrllimited="true" ctrlrange="-200 200"/>
        <motor class="h1" name="right_hip_roll" joint="right_hip_roll" ctrllimited="true" ctrlrange="-200 200"/>
        <motor class="h1" name="right_hip_pitch" joint="right_hip_pitch" ctrllimited="true" ctrlrange="-200 200"/>
        <motor class="h1" name="right_knee" joint="right_knee" ctrllimited="true" ctrlrange="-300 300"/>
        <motor class="h1" name="right_ankle" joint="right_ankle" ctrllimited="true" ctrlrange="-40 40"/>

        <motor class="h1" name="torso" joint="torso" ctrlrange="-200 200"/>

        <motor class="h1" name="left_shoulder_pitch" joint="left_shoulder_pitch" ctrllimited="true" ctrlrange="-40 40"/>
        <motor class="h1" name="left_shoulder_roll" joint="left_shoulder_roll" ctrllimited="true" ctrlrange="-40 40"/>
        <motor class="h1" name="left_shoulder_yaw" joint="left_shoulder_yaw" ctrllimited="true" ctrlrange="-18 18"/>
        <motor class="h1" name="left_elbow" joint="left_elbow" ctrllimited="true" ctrlrange="-18 18"/>

        <motor class="h1" name="right_shoulder_pitch" joint="right_shoulder_pitch" ctrllimited="true" ctrlrange="-40 40"/>
        <motor class="h1" name="right_shoulder_roll" joint="right_shoulder_roll" ctrllimited="true" ctrlrange="-40 40"/>
        <motor class="h1" name="right_shoulder_yaw" joint="right_shoulder_yaw" ctrllimited="true" ctrlrange="-18 18"/>
        <motor class="h1" name="right_elbow" joint="right_elbow" ctrllimited="true" ctrlrange="-18 18"/>

<!--        <motor class="h1" name="left_hip_yaw" joint="left_hip_yaw"/>-->
<!--        <motor class="h1" name="left_hip_roll" joint="left_hip_roll"/>-->
<!--        <motor class="h1" name="left_hip_pitch" joint="left_hip_pitch"/>-->
<!--        <motor class="h1" name="left_knee" joint="left_knee"/>-->
<!--        <motor class="h1" name="left_ankle" joint="left_ankle"/>-->

<!--        <motor class="h1" name="right_hip_yaw" joint="right_hip_yaw"/>-->
<!--        <motor class="h1" name="right_hip_roll" joint="right_hip_roll"/>-->
<!--        <motor class="h1" name="right_hip_pitch" joint="right_hip_pitch"/>-->
<!--        <motor class="h1" name="right_knee" joint="right_knee"/>-->
<!--        <motor class="h1" name="right_ankle" joint="right_ankle"/>-->

<!--        <motor class="h1" name="torso" joint="torso"/>-->

<!--        <motor class="h1" name="left_shoulder_pitch" joint="left_shoulder_pitch"/>-->
<!--        <motor class="h1" name="left_shoulder_roll" joint="left_shoulder_roll"/>-->
<!--        <motor class="h1" name="left_shoulder_yaw" joint="left_shoulder_yaw"/>-->
<!--        <motor class="h1" name="left_elbow" joint="left_elbow"/>-->

<!--        <motor class="h1" name="right_shoulder_pitch" joint="right_shoulder_pitch"/>-->
<!--        <motor class="h1" name="right_shoulder_roll" joint="right_shoulder_roll"/>-->
<!--        <motor class="h1" name="right_shoulder_yaw" joint="right_shoulder_yaw"/>-->
<!--        <motor class="h1" name="right_elbow" joint="right_elbow"/>-->
<!-- 
        <position joint="joint_l_pinky_distal" name="joint_l_pinky_distal" ctrlrange="0 1.87" kp="2" forcelimited="true"
                  forcerange="-20 20"/>
        <position joint="joint_l_pinky_proximal" name="joint_l_pinky_proximal" ctrlrange="0 1.62" kp="2"
                  forcelimited="true" forcerange="-20 20"/>
        <position joint="joint_l_ring_distal" name="joint_l_ring_distal" ctrlrange="0 1.75" kp="2" forcelimited="true"
                  forcerange="-20 20"/>
        <position joint="joint_l_ring_proximal" name="joint_l_ring_proximal" ctrlrange="0 1.62" kp="2"
                  forcelimited="true"
                  forcerange="-20 20"/>
        <position joint="joint_l_middle_distal" name="joint_l_middle_distal" ctrlrange="0 1.82" kp="2"
                  forcelimited="true"
                  forcerange="-20 20"/>
        <position joint="joint_l_middle_proximal" name="joint_l_middle_proximal" ctrlrange="0 1.62" kp="2"
                  forcelimited="true" forcerange="-20 20"/>
        <position joint="joint_l_index_distal" name="joint_l_index_distal" ctrlrange="0 1.82" kp="2" forcelimited="true"
                  forcerange="-20 20"/>
        <position joint="joint_l_index_proximal" name="joint_l_index_proximal" ctrlrange="0 1.62" kp="2"
                  forcelimited="true" forcerange="-20 20"/>
        <position joint="joint_l_thumb_distal" name="joint_l_thumb_distal" ctrlrange="0 0.77" kp="2" forcelimited="true"
                  forcerange="-20 20"/>
        <position joint="joint_l_thumb_middle" name="joint_l_thumb_middle" ctrlrange="0 0.68" kp="2" forcelimited="true"
                  forcerange="-20 20"/>
        <position joint="joint_l_thumb_proximal_2" name="joint_l_thumb_proximal_2" ctrlrange="0 0.68" kp="2"
                  forcelimited="true" forcerange="-20 20"/>
        <position joint="joint_l_thumb_proximal_1" name="joint_l_thumb_proximal_1" ctrlrange="0 1.3" kp="4"
                  forcelimited="true" forcerange="-20 20"/>
        <position joint="joint_r_pinky_distal" name="joint_r_pinky_distal" ctrlrange="0 1.87" kp="2" forcelimited="true"
                  forcerange="-20 20"/>
        <position joint="joint_r_pinky_proximal" name="joint_r_pinky_proximal" ctrlrange="0 1.62" kp="2"
                  forcelimited="true" forcerange="-20 20"/>
        <position joint="joint_r_ring_distal" name="joint_r_ring_distal" ctrlrange="0 1.75" kp="2" forcelimited="true"
                  forcerange="-20 20"/>
        <position joint="joint_r_ring_proximal" name="joint_r_ring_proximal" ctrlrange="0 1.62" kp="2"
                  forcelimited="true"
                  forcerange="-20 20"/>
        <position joint="joint_r_middle_distal" name="joint_r_middle_distal" ctrlrange="0 1.82" kp="2"
                  forcelimited="true"
                  forcerange="-20 20"/>
        <position joint="joint_r_middle_proximal" name="joint_r_middle_proximal" ctrlrange="0 1.62" kp="2"
                  forcelimited="true" forcerange="-20 20"/>
        <position joint="joint_r_index_distal" name="joint_r_index_distal" ctrlrange="0 1.82" kp="2" forcelimited="true"
                  forcerange="-20 20"/>
        <position joint="joint_r_index_proximal" name="joint_r_index_proximal" ctrlrange="0 1.62" kp="2"
                  forcelimited="true" forcerange="-20 20"/>
        <position joint="joint_r_thumb_distal" name="joint_r_thumb_distal" ctrlrange="0 0.77" kp="2" forcelimited="true"
                  forcerange="-20 20"/>
        <position joint="joint_r_thumb_middle" name="joint_r_thumb_middle" ctrlrange="0 0.68" kp="2" forcelimited="true"
                  forcerange="-20 20"/>
        <position joint="joint_r_thumb_proximal_2" name="joint_r_thumb_proximal_2" ctrlrange="0 0.68" kp="2"
                  forcelimited="true" forcerange="-20 20"/>
        <position joint="joint_r_thumb_proximal_1" name="joint_r_thumb_proximal_1" ctrlrange="0 1.3" kp="4"
                  forcelimited="true" forcerange="-20 20"/> -->

        <!-- <motor joint="joint_l_pinky_distal" name="joint_l_pinky_distal" ctrlrange="-20 20"/>
        <motor joint="joint_l_pinky_proximal" name="joint_l_pinky_proximal" ctrlrange="-20 20"/>
        <motor joint="joint_l_ring_distal" name="joint_l_ring_distal" ctrlrange="-20 20"/>
        <motor joint="joint_l_ring_proximal" name="joint_l_ring_proximal" ctrlrange="-20 20"/>
        <motor joint="joint_l_middle_distal" name="joint_l_middle_distal" ctrlrange="-20 20"/>
        <motor joint="joint_l_middle_proximal" name="joint_l_middle_proximal" ctrlrange="-20 20"/>
        <motor joint="joint_l_index_distal" name="joint_l_index_distal" ctrlrange="-20 20"/>
        <motor joint="joint_l_index_proximal" name="joint_l_index_proximal" ctrlrange="-20 20"/>
        <motor joint="joint_l_thumb_distal" name="joint_l_thumb_distal" ctrlrange="-20 20"/>
        <motor joint="joint_l_thumb_middle" name="joint_l_thumb_middle" ctrlrange="-20 20"/>
        <motor joint="joint_l_thumb_proximal_2" name="joint_l_thumb_proximal_2" ctrlrange="-20 20"/>
        <motor joint="joint_l_thumb_proximal_1" name="joint_l_thumb_proximal_1" ctrlrange="-20 20"/>
        <motor joint="joint_r_pinky_distal" name="joint_r_pinky_distal" ctrlrange="-20 20"/>
        <motor joint="joint_r_pinky_proximal" name="joint_r_pinky_proximal" ctrlrange="-20 20"/>
        <motor joint="joint_r_ring_distal" name="joint_r_ring_distal" ctrlrange="-20 20"/>
        <motor joint="joint_r_ring_proximal" name="joint_r_ring_proximal" ctrlrange="-20 20"/>
        <motor joint="joint_r_middle_distal" name="joint_r_middle_distal" ctrlrange="-20 20"/>
        <motor joint="joint_r_middle_proximal" name="joint_r_middle_proximal" ctrlrange="-20 20"/>
        <motor joint="joint_r_index_distal" name="joint_r_index_distal" ctrlrange="-20 20"/>
        <motor joint="joint_r_index_proximal" name="joint_r_index_proximal" ctrlrange="-20 20"/>
        <motor joint="joint_r_thumb_distal" name="joint_r_thumb_distal" ctrlrange="-20 20"/>
        <motor joint="joint_r_thumb_middle" name="joint_r_thumb_middle" ctrlrange="-20 20"/>
        <motor joint="joint_r_thumb_proximal_2" name="joint_r_thumb_proximal_2" ctrlrange="-20 20"/>
        <motor joint="joint_r_thumb_proximal_1" name="joint_r_thumb_proximal_1" ctrlrange="-20 20"/> -->


      <motor joint="joint_l_pinky_distal" name="joint_l_pinky_distal" ctrlrange="-1 1"/>
      <motor joint="joint_l_pinky_proximal" name="joint_l_pinky_proximal" ctrlrange="-1 1"/>
      <motor joint="joint_l_ring_distal" name="joint_l_ring_distal" ctrlrange="-1 1"/>
      <motor joint="joint_l_ring_proximal" name="joint_l_ring_proximal" ctrlrange="-1 1"/>
      <motor joint="joint_l_middle_distal" name="joint_l_middle_distal" ctrlrange="-1 1"/>
      <motor joint="joint_l_middle_proximal" name="joint_l_middle_proximal" ctrlrange="-1 1"/>
      <motor joint="joint_l_index_distal" name="joint_l_index_distal" ctrlrange="-1 1"/>
      <motor joint="joint_l_index_proximal" name="joint_l_index_proximal" ctrlrange="-1 1"/>
      <motor joint="joint_l_thumb_distal" name="joint_l_thumb_distal" ctrlrange="-1 1"/>
      <motor joint="joint_l_thumb_middle" name="joint_l_thumb_middle" ctrlrange="-1 1"/>
      <motor joint="joint_l_thumb_proximal_2" name="joint_l_thumb_proximal_2" ctrlrange="-1 1"/>
      <motor joint="joint_l_thumb_proximal_1" name="joint_l_thumb_proximal_1" ctrlrange="-1 1"/>
      <motor joint="joint_r_pinky_distal" name="joint_r_pinky_distal" ctrlrange="-1 1"/>
      <motor joint="joint_r_pinky_proximal" name="joint_r_pinky_proximal" ctrlrange="-1 1"/>
      <motor joint="joint_r_ring_distal" name="joint_r_ring_distal" ctrlrange="-1 1"/>
      <motor joint="joint_r_ring_proximal" name="joint_r_ring_proximal" ctrlrange="-1 1"/>
      <motor joint="joint_r_middle_distal" name="joint_r_middle_distal" ctrlrange="-1 1"/>
      <motor joint="joint_r_middle_proximal" name="joint_r_middle_proximal" ctrlrange="-1 1"/>
      <motor joint="joint_r_index_distal" name="joint_r_index_distal" ctrlrange="-1 1"/>
      <motor joint="joint_r_index_proximal" name="joint_r_index_proximal" ctrlrange="-1 1"/>
      <motor joint="joint_r_thumb_distal" name="joint_r_thumb_distal" ctrlrange="-1 1"/>
      <motor joint="joint_r_thumb_middle" name="joint_r_thumb_middle" ctrlrange="-1 1"/>
      <motor joint="joint_r_thumb_proximal_2" name="joint_r_thumb_proximal_2" ctrlrange="-1 1"/>
      <motor joint="joint_r_thumb_proximal_1" name="joint_r_thumb_proximal_1" ctrlrange="-1 1"/>



        
    </actuator>

    <sensor>
        <force name="left_force_ee" site="left_ft_frame"/>
        <torque name="left_torque_ee" site="left_ft_frame"/>
        <force name="right_force_ee" site="right_ft_frame"/>
        <torque name="right_torque_ee" site="right_ft_frame"/>
    </sensor>

</mujoco>
